<?xml version="1.0" ?>
<!-- =================================================================================== -->
<!-- |    This document was autogenerated by xacro from /home/rui/avatar_ws/src/avatar_simulation/avatar_gripper_description/urdf/avatar_gripper_3f_example.xacro | -->
<!-- |    EDITING THIS FILE BY HAND IS NOT RECOMMENDED                                 | -->
<!-- =================================================================================== -->
<robot name="avatar_gripper_3f_model">
  <link name="right_thumb_base">
    <inertial>
      <mass value="0.5"/>
      <inertia ixx="4E-5" ixy="0.0" ixz="0.0" iyy="4E-5" iyz="0.0" izz="4E-5"/>
    </inertial>
    <visual>
      <origin rpy="0 0   0" xyz="0 0 0"/>
      <geometry>
        <mesh filename="package://avatar_gripper_description/meshes/right/thumb_base_extra.obj"/>
      </geometry>
      <material name="">
        <color rgba="0.9 0.9 0.9 1"/>
      </material>
    </visual>
    <collision>
      <origin rpy="0 0 0" xyz="0 0 -0.02"/>
      <geometry>
        <cylinder length="0.036" radius="0.01"/>
      </geometry>
    </collision>
    <collision>
      <origin xyz="0 0 -0.0020000000000000018"/>
      <geometry>
        <sphere radius="0.01"/>
      </geometry>
    </collision>
    <collision>
      <origin xyz="0 0 -0.038"/>
      <geometry>
        <sphere radius="0.01"/>
      </geometry>
    </collision>
  </link>
  <link name="right_thumb_knuckle">
    <inertial>
      <mass value="0.5"/>
      <inertia ixx="4E-5" ixy="0.0" ixz="0.0" iyy="4E-5" iyz="0.0" izz="4E-5"/>
    </inertial>
    <visual>
      <origin rpy="0 0 0" xyz="0 0 0"/>
      <geometry>
        <mesh filename="package://avatar_gripper_description/meshes/right/thumb_knuckle.obj"/>
      </geometry>
      <material name="">
        <color rgba="0.9 0.9 0.9 1"/>
      </material>
    </visual>
    <collision>
      <origin rpy="0 1.5707963267948966 0" xyz="0.0235 0 0"/>
      <geometry>
        <cylinder length="0.047" radius="0.009"/>
      </geometry>
    </collision>
    <collision>
      <origin xyz="0.047 0 0"/>
      <geometry>
        <sphere radius="0.009"/>
      </geometry>
    </collision>
    <collision>
      <origin xyz="0.0 0 0"/>
      <geometry>
        <sphere radius="0.009"/>
      </geometry>
    </collision>
  </link>
  <joint name="right_thumb_knuckle_joint" type="revolute">
    <origin rpy="0 3.064 0" xyz="0 0 0"/>
    <parent link="right_thumb_base"/>
    <child link="right_thumb_knuckle"/>
    <axis xyz="0 1 0"/>
    <limit effort="1000" lower="-1.0" upper="0.4" velocity="2.0"/>
    <mimic joint="right_thumb_flex_motor_joint" multiplier="0.28" offset="0"/>
  </joint>
  <link name="right_thumb_finger">
    <inertial>
      <mass value="0.5"/>
      <inertia ixx="4E-5" ixy="0.0" ixz="0.0" iyy="4E-5" iyz="0.0" izz="4E-5"/>
    </inertial>
    <visual>
      <origin rpy="0 0 0" xyz="0 0 0"/>
      <geometry>
        <mesh filename="package://avatar_gripper_description/meshes/right/thumb_fingertip.obj"/>
      </geometry>
      <material name="">
        <color rgba="0.9 0.9 0.9 1"/>
      </material>
    </visual>
    <collision>
      <origin rpy="0 1.5707963267948966 0" xyz="0.02 0 0"/>
      <geometry>
        <cylinder length="0.041" radius="0.008"/>
      </geometry>
    </collision>
    <collision>
      <origin xyz="0.0405 0 0"/>
      <geometry>
        <sphere radius="0.008"/>
      </geometry>
    </collision>
    <collision>
      <origin xyz="-0.0005000000000000004 0 0"/>
      <geometry>
        <sphere radius="0.008"/>
      </geometry>
    </collision>
  </link>
  <joint name="right_thumb_finger_joint" type="revolute">
    <!-- <origin xyz="0.04568 0 0.01106" rpy="0 0.57 0"/> -->
    <origin rpy="0 -0.12813170079773184 0" xyz="0.047 0 0"/>
    <parent link="right_thumb_knuckle"/>
    <child link="right_thumb_finger"/>
    <axis xyz="0 1 0"/>
    <limit effort="1000" lower="-0.8" upper="0" velocity="2.0"/>
    <mimic joint="right_thumb_flex_motor_joint" multiplier="0.24" offset="0"/>
  </joint>
  <link name="right_thumb_swivel_link">
    <inertial>
      <mass value="0.1"/>
      <inertia ixx="4E-5" ixy="0.0" ixz="0.0" iyy="4E-5" iyz="0.0" izz="4E-5"/>
    </inertial>
    <visual>
      <origin rpy="0 0 0" xyz="0 0 0"/>
      <geometry>
        <mesh filename="package://avatar_gripper_description/meshes/right/thumb_swivel_link.obj"/>
      </geometry>
      <material name="">
        <color rgba="0.9 0.9 0.9 1"/>
      </material>
    </visual>
  </link>
  <joint name="right_thumb_swivel_joint" type="revolute">
    <origin rpy="0 0 0" xyz="0 0 0.0173"/>
    <parent link="right_index_base_connector"/>
    <child link="right_thumb_swivel_link"/>
    <axis xyz="0 0 1"/>
    <limit effort="1000" lower="0" upper="1.7" velocity="2.0"/>
    <mimic joint="right_thumb_swivel_motor_joint" multiplier="-0.6075" offset="0.43"/>
  </joint>
  <joint name="right_thumb_base_swivel_joint" type="fixed">
    <origin rpy="0 -0.5235987755982988 0" xyz="-0.03742 0 0.05089"/>
    <parent link="right_thumb_swivel_link"/>
    <child link="right_thumb_base"/>
  </joint>
  <link name="right_index_base_connector">
    <inertial>
      <mass value="0.02"/>
      <inertia ixx="4E-5" ixy="0.0" ixz="0.0" iyy="4E-5" iyz="0.0" izz="4E-5"/>
    </inertial>
    <visual>
      <origin rpy="0 0 0" xyz="0 0 0"/>
      <geometry>
        <mesh filename="package://avatar_gripper_description/meshes/right/index_base_connector.obj"/>
      </geometry>
      <material name="">
        <color rgba="0.9 0.9 0.9 1"/>
      </material>
    </visual>
    <collision>
      <origin rpy="0 0 0" xyz="-0.008 0 0.013"/>
      <geometry>
        <sphere radius="0.015"/>
      </geometry>
    </collision>
    <collision>
      <origin rpy="0 0 0" xyz="0.008 0 0.013"/>
      <geometry>
        <sphere radius="0.015"/>
      </geometry>
    </collision>
  </link>
  <link name="right_index_knuckle">
    <inertial>
      <mass value="0.5"/>
      <inertia ixx="4E-5" ixy="0.0" ixz="0.0" iyy="4E-5" iyz="0.0" izz="4E-5"/>
    </inertial>
    <visual>
      <origin rpy="0 0 0" xyz="0 0 0"/>
      <geometry>
        <mesh filename="package://avatar_gripper_description/meshes/right/index_knuckle.obj"/>
      </geometry>
      <material name="">
        <color rgba="0.9 0.9 0.9 1"/>
      </material>
    </visual>
    <collision>
      <origin rpy="0 1.5707963267948966 0" xyz="0.02 0 0"/>
      <geometry>
        <cylinder length="0.04" radius="0.01"/>
      </geometry>
    </collision>
    <collision>
      <origin xyz="0.04 0 0"/>
      <geometry>
        <sphere radius="0.01"/>
      </geometry>
    </collision>
    <collision>
      <origin xyz="0.0 0 0"/>
      <geometry>
        <sphere radius="0.01"/>
      </geometry>
    </collision>
  </link>
  <joint name="right_index_knuckle_joint" type="revolute">
    <origin rpy="-2.3053 1.3087 -2.2008" xyz="-0.021564878 0.008545 -0.0024358"/>
    <parent link="right_index_base_connector"/>
    <child link="right_index_knuckle"/>
    <axis xyz="0 0 1"/>
    <limit effort="1000" lower="-0.8" upper="0" velocity="2.0"/>
    <mimic joint="right_index_flex_motor_joint" multiplier="0.4016" offset="0"/>
  </joint>
  <link name="right_index_fingertip">
    <inertial>
      <mass value="0.5"/>
      <inertia ixx="4E-5" ixy="0.0" ixz="0.0" iyy="4E-5" iyz="0.0" izz="4E-5"/>
    </inertial>
    <visual>
      <origin rpy="0 0 0" xyz="0 0 0"/>
      <geometry>
        <mesh filename="package://avatar_gripper_description/meshes/right/index_fingertip.obj"/>
      </geometry>
      <material name="">
        <color rgba="0.9 0.9 0.9 1"/>
      </material>
    </visual>
    <collision>
      <origin rpy="0 1.5707963267948966 0" xyz="0.013 0 0"/>
      <geometry>
        <cylinder length="0.026" radius="0.008"/>
      </geometry>
    </collision>
    <collision>
      <origin xyz="0.026 0 0"/>
      <geometry>
        <sphere radius="0.008"/>
      </geometry>
    </collision>
    <collision>
      <origin xyz="0.0 0 0"/>
      <geometry>
        <sphere radius="0.008"/>
      </geometry>
    </collision>
    <collision>
      <origin rpy="0 1.5707963267948966 -0.67" xyz="0.038 -0.009 0"/>
      <geometry>
        <cylinder length="0.023" radius="0.008"/>
      </geometry>
    </collision>
    <collision>
      <origin xyz="0.04701394915762976 -0.016141338850920436 0"/>
      <geometry>
        <sphere radius="0.008"/>
      </geometry>
    </collision>
    <collision>
      <origin xyz="0.028986050842370235 -0.001858661149079563 0"/>
      <geometry>
        <sphere radius="0.008"/>
      </geometry>
    </collision>
  </link>
  <joint name="right_index_fingertip_joint" type="revolute">
    <origin rpy="0 0 0.313" xyz="0.04499 0 0"/>
    <parent link="right_index_knuckle"/>
    <child link="right_index_fingertip"/>
    <axis xyz="0 0 1"/>
    <limit effort="1000" lower="-0.8" upper="0" velocity="2.0"/>
    <mimic joint="right_index_flex_motor_joint" multiplier="0.4" offset="0"/>
  </joint>
  <link name="right_middle_knuckle">
    <inertial>
      <mass value="0.5"/>
      <inertia ixx="4E-5" ixy="0.0" ixz="0.0" iyy="4E-5" iyz="0.0" izz="4E-5"/>
    </inertial>
    <visual>
      <origin rpy="0 0 0" xyz="0 0 0"/>
      <geometry>
        <mesh filename="package://avatar_gripper_description/meshes/right/index_knuckle.obj"/>
      </geometry>
      <material name="">
        <color rgba="0.9 0.9 0.9 1"/>
      </material>
    </visual>
    <collision>
      <origin rpy="0 1.5707963267948966 0" xyz="0.02 0 0"/>
      <geometry>
        <cylinder length="0.04" radius="0.01"/>
      </geometry>
    </collision>
    <collision>
      <origin xyz="0.04 0 0"/>
      <geometry>
        <sphere radius="0.01"/>
      </geometry>
    </collision>
    <collision>
      <origin xyz="0.0 0 0"/>
      <geometry>
        <sphere radius="0.01"/>
      </geometry>
    </collision>
  </link>
  <joint name="right_middle_knuckle_joint" type="revolute">
    <origin rpy="-0.8363 1.3087 -0.9408" xyz="0.02156 0.008545 -0.0024358"/>
    <parent link="right_index_base_connector"/>
    <child link="right_middle_knuckle"/>
    <axis xyz="0 0 1"/>
    <limit effort="1000" lower="-0.8" upper="0" velocity="2.0"/>
    <mimic joint="right_index_knuckle_joint" multiplier="1" offset="0"/>
  </joint>
  <link name="right_middle_fingertip">
    <inertial>
      <mass value="0.5"/>
      <inertia ixx="4E-5" ixy="0.0" ixz="0.0" iyy="4E-5" iyz="0.0" izz="4E-5"/>
    </inertial>
    <visual>
      <origin rpy="0 0 0" xyz="0 0 0"/>
      <geometry>
        <mesh filename="package://avatar_gripper_description/meshes/right/index_fingertip.obj"/>
      </geometry>
      <material name="">
        <color rgba="0.9 0.9 0.9 1"/>
      </material>
    </visual>
    <collision>
      <origin rpy="0 1.5707963267948966 0" xyz="0.013 0 0"/>
      <geometry>
        <cylinder length="0.026" radius="0.008"/>
      </geometry>
    </collision>
    <collision>
      <origin xyz="0.026 0 0"/>
      <geometry>
        <sphere radius="0.008"/>
      </geometry>
    </collision>
    <collision>
      <origin xyz="0.0 0 0"/>
      <geometry>
        <sphere radius="0.008"/>
      </geometry>
    </collision>
    <collision>
      <origin rpy="0 1.5707963267948966 -0.67" xyz="0.038 -0.009 0"/>
      <geometry>
        <cylinder length="0.023" radius="0.008"/>
      </geometry>
    </collision>
    <collision>
      <origin xyz="0.04701394915762976 -0.016141338850920436 0"/>
      <geometry>
        <sphere radius="0.008"/>
      </geometry>
    </collision>
    <collision>
      <origin xyz="0.028986050842370235 -0.001858661149079563 0"/>
      <geometry>
        <sphere radius="0.008"/>
      </geometry>
    </collision>
  </link>
  <joint name="right_middle_fingertip_joint" type="revolute">
    <origin rpy="0 0 0.313" xyz="0.04499 0 0"/>
    <parent link="right_middle_knuckle"/>
    <child link="right_middle_fingertip"/>
    <axis xyz="0 0 1"/>
    <limit effort="1000" lower="-0.8" upper="0" velocity="2.0"/>
    <mimic joint="right_index_fingertip_joint" multiplier="1" offset="0"/>
  </joint>
  <link name="right_gripper_base">
    <inertial>
      <mass value="2.0"/>
      <inertia ixx="7.11E-3" ixy="0.0" ixz="0.0" iyy="7.11E-3" iyz="0.0" izz="7.11E-3"/>
    </inertial>
    <visual>
      <origin rpy="0 0 0" xyz="0 0 0"/>
      <geometry>
        <mesh filename="package://avatar_gripper_description/meshes/right/gripper_base.obj"/>
      </geometry>
      <material name="">
        <color rgba="0.9 0.9 0.7 1"/>
      </material>
    </visual>
    <!-- <collision>
        <origin xyz="0 0 -0.03" rpy="0 0 0"/>
        <geometry>
          <box size="0.1 0.1 0.06"/>
        </geometry>
      </collision> -->
  </link>
  <joint name="right_gripper_base_joint" type="fixed">
    <origin rpy="1.57 0 0" xyz="0.00736 0.139 -0.066017"/>
    <parent link="right_gripper_base"/>
    <child link="right_index_base_connector"/>
  </joint>
  <link name="right_thumb_flex_motor">
    <inertial>
      <mass value="0.25"/>
      <inertia ixx="1.463E-04" ixy="0" ixz="0" iyy="1.463E-04" iyz="0" izz="1.463E-04"/>
    </inertial>
    <visual>
      <origin rpy="0 0 0" xyz="0 0 0"/>
      <geometry>
        <cylinder length="0.01" radius="0.02"/>
      </geometry>
    </visual>
  </link>
  <joint name="right_thumb_flex_motor_joint" type="revolute">
    <origin rpy="0 0 0" xyz="-0.05 0.0 0.0"/>
    <parent link="right_gripper_base"/>
    <child link="right_thumb_flex_motor"/>
    <axis xyz="0 0 1"/>
    <limit effort="1000" lower="-2.3" upper="-0.08" velocity="2.0"/>
  </joint>
  <link name="right_thumb_swivel_motor">
    <inertial>
      <mass value="0.25"/>
      <inertia ixx="1.463E-04" ixy="0" ixz="0" iyy="1.463E-04" iyz="0" izz="1.463E-04"/>
    </inertial>
    <visual>
      <origin rpy="0 0 0" xyz="0 0 0"/>
      <geometry>
        <cylinder length="0.01" radius="0.02"/>
      </geometry>
    </visual>
  </link>
  <joint name="right_thumb_swivel_motor_joint" type="revolute">
    <origin rpy="0 0 0" xyz="-0.1 0.0 0.0"/>
    <parent link="right_gripper_base"/>
    <child link="right_thumb_swivel_motor"/>
    <axis xyz="0 0 1"/>
    <limit effort="1000" lower="-2.3" upper="-0.05" velocity="2.0"/>
  </joint>
  <link name="right_index_flex_motor">
    <inertial>
      <mass value="0.25"/>
      <inertia ixx="1.463E-04" ixy="0" ixz="0" iyy="1.463E-04" iyz="0" izz="1.463E-04"/>
    </inertial>
    <visual>
      <origin rpy="0 0 0" xyz="0 0 0"/>
      <geometry>
        <cylinder length="0.01" radius="0.02"/>
      </geometry>
    </visual>
  </link>
  <joint name="right_index_flex_motor_joint" type="revolute">
    <origin rpy="0 0 0" xyz="0.0 0.0 0.0"/>
    <parent link="right_gripper_base"/>
    <child link="right_index_flex_motor"/>
    <axis xyz="0 0 1"/>
    <limit effort="1000" lower="-2.3" upper="-0.08" velocity="2.0"/>
  </joint>
  <transmission name="right_thumb_knuckle_joint_transmission">
    <type>transmission_interface/SimpleTransmission</type>
    <joint name="right_thumb_knuckle_joint">
      <hardwareInterface>PositionJointInterface</hardwareInterface>
    </joint>
    <actuator name="right_thumb_knuckle_joint_actuator">
      <hardwareInterface>PositionJointInterface</hardwareInterface>
      <mechanicalReduction>1</mechanicalReduction>
    </actuator>
  </transmission>
  <transmission name="right_thumb_finger_joint_transmission">
    <type>transmission_interface/SimpleTransmission</type>
    <joint name="right_thumb_finger_joint">
      <hardwareInterface>PositionJointInterface</hardwareInterface>
    </joint>
    <actuator name="right_thumb_finger_joint_actuator">
      <hardwareInterface>PositionJointInterface</hardwareInterface>
      <mechanicalReduction>1</mechanicalReduction>
    </actuator>
  </transmission>
  <transmission name="right_thumb_swivel_joint_transmission">
    <type>transmission_interface/SimpleTransmission</type>
    <joint name="right_thumb_swivel_joint">
      <hardwareInterface>PositionJointInterface</hardwareInterface>
    </joint>
    <actuator name="right_thumb_swivel_joint_actuator">
      <hardwareInterface>PositionJointInterface</hardwareInterface>
      <mechanicalReduction>1</mechanicalReduction>
    </actuator>
  </transmission>
  <transmission name="right_index_knuckle_joint_transmission">
    <type>transmission_interface/SimpleTransmission</type>
    <joint name="right_index_knuckle_joint">
      <hardwareInterface>PositionJointInterface</hardwareInterface>
    </joint>
    <actuator name="right_index_knuckle_joint_actuator">
      <hardwareInterface>PositionJointInterface</hardwareInterface>
      <mechanicalReduction>1</mechanicalReduction>
    </actuator>
  </transmission>
  <transmission name="right_index_fingertip_joint_transmission">
    <type>transmission_interface/SimpleTransmission</type>
    <joint name="right_index_fingertip_joint">
      <hardwareInterface>PositionJointInterface</hardwareInterface>
    </joint>
    <actuator name="right_index_fingertip_joint_actuator">
      <hardwareInterface>PositionJointInterface</hardwareInterface>
      <mechanicalReduction>1</mechanicalReduction>
    </actuator>
  </transmission>
  <transmission name="right_middle_knuckle_joint_transmission">
    <type>transmission_interface/SimpleTransmission</type>
    <joint name="right_middle_knuckle_joint">
      <hardwareInterface>PositionJointInterface</hardwareInterface>
    </joint>
    <actuator name="right_middle_knuckle_joint_actuator">
      <hardwareInterface>PositionJointInterface</hardwareInterface>
      <mechanicalReduction>1</mechanicalReduction>
    </actuator>
  </transmission>
  <transmission name="right_middle_fingertip_joint_transmission">
    <type>transmission_interface/SimpleTransmission</type>
    <joint name="right_middle_fingertip_joint">
      <hardwareInterface>PositionJointInterface</hardwareInterface>
    </joint>
    <actuator name="right_middle_fingertip_joint_actuator">
      <hardwareInterface>PositionJointInterface</hardwareInterface>
      <mechanicalReduction>1</mechanicalReduction>
    </actuator>
  </transmission>
  <transmission name="right_thumb_flex_motor_joint_transmission">
    <type>transmission_interface/SimpleTransmission</type>
    <joint name="right_thumb_flex_motor_joint">
      <hardwareInterface>PositionJointInterface</hardwareInterface>
    </joint>
    <actuator name="right_thumb_flex_motor_joint_actuator">
      <hardwareInterface>PositionJointInterface</hardwareInterface>
      <mechanicalReduction>1</mechanicalReduction>
    </actuator>
  </transmission>
  <transmission name="right_thumb_swivel_motor_joint_transmission">
    <type>transmission_interface/SimpleTransmission</type>
    <joint name="right_thumb_swivel_motor_joint">
      <hardwareInterface>PositionJointInterface</hardwareInterface>
    </joint>
    <actuator name="right_thumb_swivel_motor_joint_actuator">
      <hardwareInterface>PositionJointInterface</hardwareInterface>
      <mechanicalReduction>1</mechanicalReduction>
    </actuator>
  </transmission>
  <transmission name="right_index_flex_motor_joint_transmission">
    <type>transmission_interface/SimpleTransmission</type>
    <joint name="right_index_flex_motor_joint">
      <hardwareInterface>PositionJointInterface</hardwareInterface>
    </joint>
    <actuator name="right_index_flex_motor_joint_actuator">
      <hardwareInterface>PositionJointInterface</hardwareInterface>
      <mechanicalReduction>1</mechanicalReduction>
    </actuator>
  </transmission>
</robot>

