<?xml version="1.0" ?>
<!-- =================================================================================== -->
<!-- |    This document was autogenerated by xacro from urdf/avatar_gripper_3f.xacro   | -->
<!-- |    EDITING THIS FILE BY HAND IS NOT RECOMMENDED                                 | -->
<!-- =================================================================================== -->
<robot name="avatar_gripper_3f_model">
  <link name="right_thumb_base">
    <inertial>
      <mass value="0.5"/>
      <inertia ixx="0.0" ixy="0.0" ixz="0.0" iyy="4E-5" iyz="0.0" izz="4E-5"/>
    </inertial>
    <visual>
      <origin rpy="0 0 0" xyz="0 0 0"/>
      <geometry>
        <mesh filename="package://avatar_gripper_description/meshes/thumb_base_extra.obj"/>
      </geometry>
      <material name="">
        <color rgba="0.9 0.9 0.9 1"/>
      </material>
    </visual>
    <collision>
      <origin rpy="0 0 0" xyz="0 0 0"/>
      <geometry>
        <mesh filename="package://avatar_gripper_description/meshes/thumb_base_extra.obj"/>
      </geometry>
    </collision>
  </link>
  <link name="right_thumb_knuckle">
    <inertial>
      <mass value="0.5"/>
      <inertia ixx="0.0" ixy="0.0" ixz="0.0" iyy="4E-5" iyz="0.0" izz="4E-5"/>
    </inertial>
    <visual>
      <origin rpy="0 0 0" xyz="0 0 0"/>
      <geometry>
        <mesh filename="package://avatar_gripper_description/meshes/thumb_knuckle.obj"/>
      </geometry>
      <material name="">
        <color rgba="0.9 0.9 0.9 1"/>
      </material>
    </visual>
    <collision>
      <origin rpy="0 0 0" xyz="0 0 0"/>
      <geometry>
        <mesh filename="package://avatar_gripper_description/meshes/thumb_knuckle.obj"/>
      </geometry>
    </collision>
  </link>
  <joint name="right_thumb_knuckle_joint" type="revolute">
    <origin rpy="0 2.75 0" xyz="0 0 0"/>
    <parent link="right_thumb_base"/>
    <child link="right_thumb_knuckle"/>
    <axis xyz="0 1 0"/>
    <limit effort="1000" lower="-1.0" upper="0.4" velocity="2.0"/>
    <mimic joint="right_thumb_flex_motor_joint" multiplier="0.5702" offsite="0"/>
  </joint>
  <link name="right_thumb_finger">
    <inertial>
      <mass value="0.5"/>
      <inertia ixx="0.0" ixy="0.0" ixz="0.0" iyy="4E-5" iyz="0.0" izz="4E-5"/>
    </inertial>
    <visual>
      <origin rpy="0 0 0" xyz="0 0 0"/>
      <geometry>
        <mesh filename="package://avatar_gripper_description/meshes/thumb_fingertip.obj"/>
      </geometry>
      <material name="">
        <color rgba="0.9 0.9 0.9 1"/>
      </material>
    </visual>
    <collision>
      <origin rpy="0 0 0" xyz="0 0 0"/>
      <geometry>
        <mesh filename="package://avatar_gripper_description/meshes/thumb_fingertip.obj"/>
      </geometry>
    </collision>
  </link>
  <joint name="right_thumb_finger_joint" type="revolute">
    <origin rpy="0 0.57 0" xyz="0.04568 0 0.01106"/>
    <parent link="right_thumb_knuckle"/>
    <child link="right_thumb_finger"/>
    <axis xyz="0 1 0"/>
    <limit effort="1000" lower="-0.8" upper="0" velocity="2.0"/>
    <mimic joint="right_thumb_flex_motor_joint" multiplier="0.6007" offsite="0"/>
  </joint>
  <link name="right_thumb_swivel_link">
    <visual>
      <origin rpy="0 0 0" xyz="0 0 0"/>
      <geometry>
        <mesh filename="package://avatar_gripper_description/meshes/thumb_swivel_link.obj"/>
      </geometry>
      <material name="">
        <color rgba="0.9 0.9 0.9 1"/>
      </material>
    </visual>
  </link>
  <joint name="right_thumb_swivel_joint" type="revolute">
    <origin rpy="0 0 0" xyz="0 0 0.0173"/>
    <parent link="right_index_base_connector"/>
    <child link="right_thumb_swivel_link"/>
    <axis xyz="0 0 1"/>
    <limit effort="1000" lower="0" upper="1.7" velocity="2.0"/>
    <mimic joint="right_thumb_swivel_motor_joint" multiplier="-0.6075" offset="0.43"/>
  </joint>
  <joint name="right_thumb_base_swivel_joint" type="fixed">
    <origin rpy="0 0 0" xyz="-0.03742 0 0.05089"/>
    <parent link="right_thumb_swivel_link"/>
    <child link="right_thumb_base"/>
  </joint>
  <link name="right_index_base_connector">
    <visual>
      <origin rpy="0 0 0" xyz="0 0 0"/>
      <geometry>
        <mesh filename="package://avatar_gripper_description/meshes/index_base_connector.obj"/>
      </geometry>
      <material name="">
        <color rgba="0.9 0.9 0.9 1"/>
      </material>
    </visual>
  </link>
  <link name="right_index_knuckle">
    <inertial>
      <mass value="0.5"/>
      <inertia ixx="0.0" ixy="0.0" ixz="0.0" iyy="4E-5" iyz="0.0" izz="4E-5"/>
    </inertial>
    <visual>
      <origin rpy="0 0 0" xyz="0 0 0"/>
      <geometry>
        <mesh filename="package://avatar_gripper_description/meshes/index_knuckle.obj"/>
      </geometry>
      <material name="">
        <color rgba="0.9 0.9 0.9 1"/>
      </material>
    </visual>
    <collision>
      <origin rpy="0 0 0" xyz="0 0 0"/>
      <geometry>
        <mesh filename="package://avatar_gripper_description/meshes/index_knuckle.obj"/>
      </geometry>
    </collision>
  </link>
  <joint name="right_index_knuckle_joint" type="revolute">
    <origin rpy="1.94428593 1.07478656 1.98996937" xyz="-0.021564878 0.008545 -0.0024358"/>
    <parent link="right_index_base_connector"/>
    <child link="right_index_knuckle"/>
    <axis xyz="0 0 1"/>
    <limit effort="1000" lower="-0.8" upper="0" velocity="2.0"/>
    <mimic joint="right_index_flex_motor_joint" multiplier="1" offsite="0"/>
  </joint>
  <link name="right_index_fingertip">
    <inertial>
      <mass value="0.5"/>
      <inertia ixx="0.0" ixy="0.0" ixz="0.0" iyy="4E-5" iyz="0.0" izz="4E-5"/>
    </inertial>
    <visual>
      <origin rpy="0 0 0" xyz="0 0 0"/>
      <geometry>
        <mesh filename="package://avatar_gripper_description/meshes/index_fingertip.obj"/>
      </geometry>
      <material name="">
        <color rgba="0.9 0.9 0.9 1"/>
      </material>
    </visual>
    <collision>
      <origin rpy="0 0 0" xyz="0 0 0"/>
      <geometry>
        <mesh filename="package://avatar_gripper_description/meshes/index_fingertip.obj"/>
      </geometry>
    </collision>
  </link>
  <joint name="right_index_fingertip_joint" type="revolute">
    <origin rpy="0 0 -0.35" xyz="0.0353829 -0.02780 0"/>
    <parent link="right_index_knuckle"/>
    <child link="right_index_fingertip"/>
    <axis xyz="0 0 1"/>
    <limit effort="1000" lower="-0.8" upper="0" velocity="2.0"/>
    <mimic joint="right_index_flex_motor_joint" multiplier="0.40" offsite="0"/>
  </joint>
  <link name="right_middle_knuckle">
    <inertial>
      <mass value="0.5"/>
      <inertia ixx="0.0" ixy="0.0" ixz="0.0" iyy="4E-5" iyz="0.0" izz="4E-5"/>
    </inertial>
    <visual>
      <origin rpy="0 0 0" xyz="0 0 0"/>
      <geometry>
        <mesh filename="package://avatar_gripper_description/meshes/index_knuckle.obj"/>
      </geometry>
      <material name="">
        <color rgba="0.9 0.9 0.9 1"/>
      </material>
    </visual>
    <collision>
      <origin rpy="0 0 0" xyz="0 0 0"/>
      <geometry>
        <mesh filename="package://avatar_gripper_description/meshes/index_knuckle.obj"/>
      </geometry>
    </collision>
  </link>
  <joint name="right_middle_knuckle_joint" type="revolute">
    <origin rpy="1.19730672 1.07478656 1.15162329" xyz="0.02156 0.008545 -0.0024358"/>
    <parent link="right_index_base_connector"/>
    <child link="right_middle_knuckle"/>
    <axis xyz="0 0 1"/>
    <limit effort="1000" lower="-0.8" upper="0" velocity="2.0"/>
    <mimic joint="right_index_knuckle_joint" multiplier="1" offset="0"/>
  </joint>
  <link name="right_middle_fingertip">
    <inertial>
      <mass value="0.5"/>
      <inertia ixx="0.0" ixy="0.0" ixz="0.0" iyy="4E-5" iyz="0.0" izz="4E-5"/>
    </inertial>
    <visual>
      <origin rpy="0 0 0" xyz="0 0 0"/>
      <geometry>
        <mesh filename="package://avatar_gripper_description/meshes/index_fingertip.obj"/>
      </geometry>
      <material name="">
        <color rgba="0.9 0.9 0.9 1"/>
      </material>
    </visual>
    <collision>
      <origin rpy="0 0 0" xyz="0 0 0"/>
      <geometry>
        <mesh filename="package://avatar_gripper_description/meshes/index_fingertip.obj"/>
      </geometry>
    </collision>
  </link>
  <joint name="right_middle_fingertip_joint" type="revolute">
    <origin rpy="0 0 -0.35" xyz="0.0353829 -0.02780 0"/>
    <parent link="right_middle_knuckle"/>
    <child link="right_middle_fingertip"/>
    <axis xyz="0 0 1"/>
    <limit effort="1000" lower="-0.8" upper="0" velocity="2.0"/>
    <mimic joint="right_index_fingertip_joint" multiplier="1" offset="0"/>
  </joint>
  <link name="right_gripper_base">
    <inertial>
      <mass value="2.0"/>
      <inertia ixx="7.11E-3" ixy="0.0" ixz="0.0" iyy="7.11E-3" iyz="0.0" izz="7.11E-3"/>
    </inertial>
    <visual>
      <origin rpy="0 0 0" xyz="0 0 0"/>
      <geometry>
        <mesh filename="package://avatar_gripper_description/meshes/gripper_base.obj"/>
      </geometry>
      <material name="">
        <color rgba="0.9 0.9 0.7 1"/>
      </material>
    </visual>
  </link>
  <joint name="right_gripper_base_joint" type="fixed">
    <origin rpy="1.57 0 0" xyz="0.00736 0.139 -0.066017"/>
    <parent link="right_gripper_base"/>
    <child link="right_index_base_connector"/>
  </joint>
  <link name="right_thumb_flex_motor">
    <inertial>
      <mass value="0.25"/>
      <inertia ixx="1.463E-04" ixy="0" ixz="0" iyy="1.463E-04" iyz="0" izz="1.463E-04"/>
    </inertial>
    <visual>
      <origin rpy="0 0 0" xyz="0 0 0"/>
      <geometry>
        <cylinder length="0.01" radius="0.02"/>
      </geometry>
    </visual>
  </link>
  <joint name="right_thumb_flex_motor_joint" type="revolute">
    <origin rpy="0 0 0" xyz="-0.05 -0.3 0"/>
    <parent link="right_gripper_base"/>
    <child link="right_thumb_flex_motor"/>
    <axis xyz="0 0 1"/>
    <limit effort="1000" lower="-1.0" upper="0.0" velocity="2.0"/>
  </joint>
  <link name="right_thumb_swivel_motor">
    <inertial>
      <mass value="0.25"/>
      <inertia ixx="1.463E-04" ixy="0" ixz="0" iyy="1.463E-04" iyz="0" izz="1.463E-04"/>
    </inertial>
    <visual>
      <origin rpy="0 0 0" xyz="0 0 0"/>
      <geometry>
        <cylinder length="0.01" radius="0.02"/>
      </geometry>
    </visual>
  </link>
  <joint name="right_thumb_swivel_motor_joint" type="revolute">
    <origin rpy="0 0 0" xyz="-0.1 -0.3 0"/>
    <parent link="right_gripper_base"/>
    <child link="right_thumb_swivel_motor"/>
    <axis xyz="0 0 1"/>
    <limit effort="1000" lower="-2.0" upper="0.0" velocity="2.0"/>
  </joint>
  <link name="right_index_flex_motor">
    <inertial>
      <mass value="0.25"/>
      <inertia ixx="1.463E-04" ixy="0" ixz="0" iyy="1.463E-04" iyz="0" izz="1.463E-04"/>
    </inertial>
    <visual>
      <origin rpy="0 0 0" xyz="0 0 0"/>
      <geometry>
        <cylinder length="0.01" radius="0.02"/>
      </geometry>
    </visual>
  </link>
  <joint name="right_index_flex_motor_joint" type="revolute">
    <origin rpy="0 0 0" xyz="0 -0.3 0"/>
    <parent link="right_gripper_base"/>
    <child link="right_index_flex_motor"/>
    <axis xyz="0 0 1"/>
    <limit effort="1000" lower="-1.0" upper="0.0" velocity="2.0"/>
  </joint>
  <!-- <xacro:macro name="attach_gripper" params="connected_to:='' arm_id:='panda' rpy:='0 0 0' xyz:='0 0 0'">
    <xacro:unless value="${connected_to == ''}">
      <joint name="${arm_id}_gripper_joint" type="fixed">
        <parent link="${connected_to}" />
        <child link="${arm_id}_hand" />
        <origin xyz="${xyz}" rpy="${rpy}" />
      </joint>
    </xacro:unless>     -->
</robot>

